Workbook
Name Periodo: DASHBOARD!$U$3

Sheet DASHBOARD
B1: Despesas Fixas | Galpão OLARIA | AD1: =IF($U$3="Ano",1,MATCH($U$3,Lançamentos!$C$4:$N$4,0)) -> 1
B3: FATURAMENTO (ANO) | G3: DESPESAS (ANO) | L3: RESULTADO (ANO) | R3: PERÍODO | U3: Ano | X3: ANO | Z3: =Cadastro!G2 -> 2026 | AD3: =IF($U$3="Ano",12,AD1) -> 12
B4: =BC18 -> 0 | G4: =BC20 -> 319728.86 | L4: =BC18-BC20 -> -319728.86
AE5: Mês | AF5: Orçado | AG5: Realizado | AH5: Mês selecionado | AU5: Realizado | AV5: Orçado | BA5: Valor | BE5: Mês | BF5: Receita | BG5: Despesa | BH5: Resultado
B6: Ano | D6: Jan | F6: Fev | H6: Mar | J6: Abr | L6: Mai | N6: Jun | P6: Jul | R6: Ago | T6: Set | V6: Out | X6: Nov | Z6: Dez | AE6: Jan | AF6: =Orçado!C23 -> 42546.762 | AG6: =IF(AI6=0,"",IF(AND($U$3<>"Ano",1=$AD$1),"",Lançamentos!C23)) -> 42546.762 | AH6: =IF(AND($U$3<>"Ano",1=$AD$1,AI6=1),Lançamentos!C23,"") | AI6: =IF(Lançamentos!C24>0,1,0) -> 1 | AL6: =Lançamentos!A5 -> Água | AM6: =Lançamentos!B5 -> Utilidades | AN6: =IF(AL6="","",SUMPRODUCT((Lançamentos!$C$3:$N$3>=$AD$1)*(Lançamentos!$C$3:$N$3<=$AD$3)*Orçado!$C5:$N5)) -> 745.52 | AO6: =IF(AL6="","",SUMPRODUCT((Lançamentos!$C$3:$N$3>=$AD$1)*(Lançamentos!$C$3:$N$3<=$AD$3)*Lançamentos!$C5:$N5)) -> 745.52 | AP6: =IF(AL6="","",IF($BC$8>0,SUMPRODUCT((Lançamentos!$C$3:$N$3>=$AD$1)*(Lançamentos!$C$3:$N$3<=$AD$3)*(Lançamentos!$C$24:$N$24>0)*Orçado!$C5:$N5),AN6)) -> 745.52 | AQ6: =IF(AL6="","",AO6+AP6/1000000+ROW()/1000000000) -> 745.52075 | AS6: =IFERROR(MATCH(LARGE($AQ$6:$AQ$25,1),$AQ$6:$AQ$25,0),"") -> 10 | AT6: =IF(AS6="","",INDEX($AL$6:$AL$25,AS6)) -> Funcionários | AU6: =IF(AS6="","",INDEX($AO$6:$AO$25,AS6)) -> 113702.48 | AV6: =IF(AS6="","",INDEX($AP$6:$AP$25,AS6)) -> 113702.48 | AX6: =Cadastro!L5 -> Pessoal | AY6: =SUMIF($AM$6:$AM$25,AX6,$AO$6:$AO$25) -> 115134.48 | AZ6: =SUMIF($AM$6:$AM$25,AX6,$AN$6:$AN$25) -> 115134.48 | BA6: =IF(SUM($AY$6:$AY$11)>0,AY6,AZ6) -> 115134.48 | BC6: =SUMPRODUCT((Lançamentos!$C$3:$N$3>=$AD$1)*(Lançamentos!$C$3:$N$3<=$AD$3)*Lançamentos!$C$23:$N$23) -> 319728.86 | BE6: =AE6 -> Jan | BF6: =IF(Faturamento!C17=0,"",Faturamento!C16) | BG6: =IF(Lançamentos!C24=0,"",Lançamentos!C23) -> 42546.762 | BH6: =IF(OR(BF6="",BG6=""),"",BF6-BG6)
AE7: Fev | AF7: =Orçado!D23 -> 37412.162 | AG7: =IF(AI7=0,"",IF(AND($U$3<>"Ano",2=$AD$1),"",Lançamentos!D23)) -> 37412.162 | AH7: =IF(AND($U$3<>"Ano",2=$AD$1,AI7=1),Lançamentos!D23,"") | AI7: =IF(Lançamentos!D24>0,1,0) -> 1 | AL7: =Lançamentos!A6 -> Energia | AM7: =Lançamentos!B6 -> Utilidades | AN7: =IF(AL7="","",SUMPRODUCT((Lançamentos!$C$3:$N$3>=$AD$1)*(Lançamentos!$C$3:$N$3<=$AD$3)*Orçado!$C6:$N6)) -> 1161.52 | AO7: =IF(AL7="","",SUMPRODUCT((Lançamentos!$C$3:$N$3>=$AD$1)*(Lançamentos!$C$3:$N$3<=$AD$3)*Lançamentos!$C6:$N6)) -> 1161.52 | AP7: =IF(AL7="","",IF($BC$8>0,SUMPRODUCT((Lançamentos!$C$3:$N$3>=$AD$1)*(Lançamentos!$C$3:$N$3<=$AD$3)*(Lançamentos!$C$24:$N$24>0)*Orçado!$C6:$N6),AN7)) -> 1161.52 | AQ7: =IF(AL7="","",AO7+AP7/1000000+ROW()/1000000000) -> 1161.5212 | AS7: =IFERROR(MATCH(LARGE($AQ$6:$AQ$25,2),$AQ$6:$AQ$25,0),"") -> 16 | AT7: =IF(AS7="","",INDEX($AL$6:$AL$25,AS7)) -> Tubete | AU7: =IF(AS7="","",INDEX($AO$6:$AO$25,AS7)) -> 112281.2 | AV7: =IF(AS7="","",INDEX($AP$6:$AP$25,AS7)) -> 112281.2 | AX7: =Cadastro!L6 -> Utilidades | AY7: =SUMIF($AM$6:$AM$25,AX7,$AO$6:$AO$25) -> 3248.72 | AZ7: =SUMIF($AM$6:$AM$25,AX7,$AN$6:$AN$25) -> 3248.72 | BA7: =IF(SUM($AY$6:$AY$11)>0,AY7,AZ7) -> 3248.72 | BC7: =SUMPRODUCT((Lançamentos!$C$3:$N$3>=$AD$1)*(Lançamentos!$C$3:$N$3<=$AD$3)*Orçado!$C$23:$N$23) -> 315259.37 | BE7: =AE7 -> Fev | BF7: =IF(Faturamento!D17=0,"",Faturamento!D16) | BG7: =IF(Lançamentos!D24=0,"",Lançamentos!D23) -> 37412.162 | BH7: =IF(OR(BF7="",BG7=""),"",BF7-BG7)
B8: ="Realizado · "&$BC$14 -> Realizado · Ano 2026 | F8: Var. vs orçado | J8: % do orçamento anual | N8: Média mensal realizada | R8: Peso da folha | W8: Lançamentos | AE8: Mar | AF8: =Orçado!E23 -> 34531.222 | AG8: =IF(AI8=0,"",IF(AND($U$3<>"Ano",3=$AD$1),"",Lançamentos!E23)) -> 35621.222 | AH8: =IF(AND($U$3<>"Ano",3=$AD$1,AI8=1),Lançamentos!E23,"") | AI8: =IF(Lançamentos!E24>0,1,0) -> 1 | AL8: =Lançamentos!A7 -> Seguro galpão | AM8: =Lançamentos!B7 -> Seguros e Segurança | AN8: =IF(AL8="","",SUMPRODUCT((Lançamentos!$C$3:$N$3>=$AD$1)*(Lançamentos!$C$3:$N$3<=$AD$3)*Orçado!$C7:$N7)) -> 2569.27 | AO8: =IF(AL8="","",SUMPRODUCT((Lançamentos!$C$3:$N$3>=$AD$1)*(Lançamentos!$C$3:$N$3<=$AD$3)*Lançamentos!$C7:$N7)) -> 2569.27 | AP8: =IF(AL8="","",IF($BC$8>0,SUMPRODUCT((Lançamentos!$C$3:$N$3>=$AD$1)*(Lançamentos!$C$3:$N$3<=$AD$3)*(Lançamentos!$C$24:$N$24>0)*Orçado!$C7:$N7),AN8)) -> 2569.27 | AQ8: =IF(AL8="","",AO8+AP8/1000000+ROW()/1000000000) -> 2569.2726 | AS8: =IFERROR(MATCH(LARGE($AQ$6:$AQ$25,3),$AQ$6:$AQ$25,0),"") -> 14 | AT8: =IF(AS8="","",INDEX($AL$6:$AL$25,AS8)) -> Combustivel | AU8: =IF(AS8="","",INDEX($AO$6:$AO$25,AS8)) -> 30733.02 | AV8: =IF(AS8="","",INDEX($AP$6:$AP$25,AS8)) -> 30733.02 | AX8: =Cadastro!L7 -> Seguros e Segurança | AY8: =SUMIF($AM$6:$AM$25,AX8,$AO$6:$AO$25) -> 5641.27 | AZ8: =SUMIF($AM$6:$AM$25,AX8,$AN$6:$AN$25) -> 5641.27 | BA8: =IF(SUM($AY$6:$AY$11)>0,AY8,AZ8) -> 5641.27 | BC8: =SUMPRODUCT((Lançamentos!$C$3:$N$3>=$AD$1)*(Lançamentos!$C$3:$N$3<=$AD$3)*(Lançamentos!$C$24:$N$24>0)*Orçado!$C$23:$N$23) -> 315259.37 | BE8: =AE8 -> Mar | BF8: =IF(Faturamento!E17=0,"",Faturamento!E16) | BG8: =IF(Lançamentos!E24=0,"",Lançamentos!E23) -> 35621.222 | BH8: =IF(OR(BF8="",BG8=""),"",BF8-BG8)
B9: =BC6 -> 319728.86 | F9: =IF(BC15=0,0,BC6/BC15-1) -> 0.014177184 | J9: =IF(BC10=0,0,BC9/BC10) -> 0 | N9: =IF(BC11=0,0,BC9/BC11) -> 35525.429 | R9: =IF(BC6>0,BC12/BC6,IF(BC7=0,0,BC13/BC7)) -> 0.36010036 | W9: =IF($U$3="Ano",COUNTIF(Lançamentos!$C$25:$N$25,"Completo")&" de 12 meses",INDEX(Lançamentos!$C$25:$N$25,$AD$1)) -> 0 de 12 meses | AE9: Abr | AF9: =Orçado!F23 -> 42089.122 | AG9: =IF(AI9=0,"",IF(AND($U$3<>"Ano",4=$AD$1),"",Lançamentos!F23)) -> 42089.122 | AH9: =IF(AND($U$3<>"Ano",4=$AD$1,AI9=1),Lançamentos!F23,"") | AI9: =IF(Lançamentos!F24>0,1,0) -> 1 | AL9: =Lançamentos!A8 -> Segurança Emive | AM9: =Lançamentos!B8 -> Seguros e Segurança | AN9: =IF(AL9="","",SUMPRODUCT((Lançamentos!$C$3:$N$3>=$AD$1)*(Lançamentos!$C$3:$N$3<=$AD$3)*Orçado!$C8:$N8)) -> 3072 | AO9: =IF(AL9="","",SUMPRODUCT((Lançamentos!$C$3:$N$3>=$AD$1)*(Lançamentos!$C$3:$N$3<=$AD$3)*Lançamentos!$C8:$N8)) -> 3072 | AP9: =IF(AL9="","",IF($BC$8>0,SUMPRODUCT((Lançamentos!$C$3:$N$3>=$AD$1)*(Lançamentos!$C$3:$N$3<=$AD$3)*(Lançamentos!$C$24:$N$24>0)*Orçado!$C8:$N8),AN9)) -> 3072 | AQ9: =IF(AL9="","",AO9+AP9/1000000+ROW()/1000000000) -> 3072.0031 | AS9: =IFERROR(MATCH(LARGE($AQ$6:$AQ$25,4),$AQ$6:$AQ$25,0),"") -> 19 | AT9: =IF(AS9="","",INDEX($AL$6:$AL$25,AS9)) -> Parcela Caminhão | AU9: =IF(AS9="","",INDEX($AO$6:$AO$25,AS9)) -> 30415.41 | AV9: =IF(AS9="","",INDEX($AP$6:$AP$25,AS9)) -> 27035.92 | AX9: =Cadastro!L8 -> Manutenção | AY9: =SUMIF($AM$6:$AM$25,AX9,$AO$6:$AO$25) -> 15991 | AZ9: =SUMIF($AM$6:$AM$25,AX9,$AN$6:$AN$25) -> 14901 | BA9: =IF(SUM($AY$6:$AY$11)>0,AY9,AZ9) -> 15991 | BC9: =SUMPRODUCT((Lançamentos!$C$3:$N$3<=$AD$3)*Lançamentos!$C$23:$N$23) -> 319728.86 | BE9: =AE9 -> Abr | BF9: =IF(Faturamento!F17=0,"",Faturamento!F16) | BG9: =IF(Lançamentos!F24=0,"",Lançamentos!F23) -> 42089.122 | BH9: =IF(OR(BF9="",BG9=""),"",BF9-BG9)
AE10: Mai | AF10: =Orçado!G23 -> 33766.052 | AG10: =IF(AI10=0,"",IF(AND($U$3<>"Ano",5=$AD$1),"",Lançamentos!G23)) -> 33766.052 | AH10: =IF(AND($U$3<>"Ano",5=$AD$1,AI10=1),Lançamentos!G23,"") | AI10: =IF(Lançamentos!G24>0,1,0) -> 1 | AL10: =Lançamentos!A9 -> Dedetização | AM10: =Lançamentos!B9 -> Manutenção | AN10: =IF(AL10="","",SUMPRODUCT((Lançamentos!$C$3:$N$3>=$AD$1)*(Lançamentos!$C$3:$N$3<=$AD$3)*Orçado!$C9:$N9)) -> 600 | AO10: =IF(AL10="","",SUMPRODUCT((Lançamentos!$C$3:$N$3>=$AD$1)*(Lançamentos!$C$3:$N$3<=$AD$3)*Lançamentos!$C9:$N9)) -> 600 | AP10: =IF(AL10="","",IF($BC$8>0,SUMPRODUCT((Lançamentos!$C$3:$N$3>=$AD$1)*(Lançamentos!$C$3:$N$3<=$AD$3)*(Lançamentos!$C$24:$N$24>0)*Orçado!$C9:$N9),AN10)) -> 600 | AQ10: =IF(AL10="","",AO10+AP10/1000000+ROW()/1000000000) -> 600.0006 | AS10: =IFERROR(MATCH(LARGE($AQ$6:$AQ$25,5),$AQ$6:$AQ$25,0),"") -> 15 | AT10: =IF(AS10="","",INDEX($AL$6:$AL$25,AS10)) -> Manutenção Veicular (peças, servico, revisao, licenciamento) | AU10: =IF(AS10="","",INDEX($AO$6:$AO$25,AS10)) -> 10623 | AV10: =IF(AS10="","",INDEX($AP$6:$AP$25,AS10)) -> 9533 | AX10: =Cadastro!L9 -> Impostos e Taxas | AY10: =SUMIF($AM$6:$AM$25,AX10,$AO$6:$AO$25) -> 2569.27 | AZ10: =SUMIF($AM$6:$AM$25,AX10,$AN$6:$AN$25) -> 2569.27 | BA10: =IF(SUM($AY$6:$AY$11)>0,AY10,AZ10) -> 2569.27 | BC10: =Cadastro!$I$23 -> 0 | BE10: =AE10 -> Mai | BF10: =IF(Faturamento!G17=0,"",Faturamento!G16) | BG10: =IF(Lançamentos!G24=0,"",Lançamentos!G23) -> 33766.052 | BH10: =IF(OR(BF10="",BG10=""),"",BF10-BG10)
B11: Orçado | D11: =BC7 -> 315259.37 | F11: Dif. | H11: =BC6-BC15 -> 4469.49 | J11: Saldo | L11: =BC10-BC9 -> -319728.86 | N11: Orçada | P11: =Cadastro!H23 -> 15577.881 | R11: Pessoal | T11: =IF(BC6>0,BC12,BC13) -> 115134.48 | W11: Itens | Y11: =IF($U$3="Ano",BC11&" c/ dados",INDEX(Lançamentos!$C$24:$N$24,$AD$1)&"/"&COUNTA(Cadastro!$B$5:$B$22)) -> 9 c/ dados | AE11: Jun | AF11: =Orçado!H23 -> 42950.282 | AG11: =IF(AI11=0,"",IF(AND($U$3<>"Ano",6=$AD$1),"",Lançamentos!H23)) -> 42950.282 | AH11: =IF(AND($U$3<>"Ano",6=$AD$1,AI11=1),Lançamentos!H23,"") | AI11: =IF(Lançamentos!H24>0,1,0) -> 1 | AL11: =Lançamentos!A10 -> IPTU | AM11: =Lançamentos!B10 -> Impostos e Taxas | AN11: =IF(AL11="","",SUMPRODUCT((Lançamentos!$C$3:$N$3>=$AD$1)*(Lançamentos!$C$3:$N$3<=$AD$3)*Orçado!$C10:$N10)) -> 2569.27 | AO11: =IF(AL11="","",SUMPRODUCT((Lançamentos!$C$3:$N$3>=$AD$1)*(Lançamentos!$C$3:$N$3<=$AD$3)*Lançamentos!$C10:$N10)) -> 2569.27 | AP11: =IF(AL11="","",IF($BC$8>0,SUMPRODUCT((Lançamentos!$C$3:$N$3>=$AD$1)*(Lançamentos!$C$3:$N$3<=$AD$3)*(Lançamentos!$C$24:$N$24>0)*Orçado!$C10:$N10),AN11)) -> 2569.27 | AQ11: =IF(AL11="","",AO11+AP11/1000000+ROW()/1000000000) -> 2569.2726 | AS11: =IFERROR(MATCH(LARGE($AQ$6:$AQ$25,6),$AQ$6:$AQ$25,0),"") -> 17 | AT11: =IF(AS11="","",INDEX($AL$6:$AL$25,AS11)) -> Manutenção Predial | AU11: =IF(AS11="","",INDEX($AO$6:$AO$25,AS11)) -> 4198 | AV11: =IF(AS11="","",INDEX($AP$6:$AP$25,AS11)) -> 4198 | AX11: =Cadastro!L10 -> Outros | AY11: =SUMIF($AM$6:$AM$25,AX11,$AO$6:$AO$25) -> 0 | AZ11: =SUMIF($AM$6:$AM$25,AX11,$AN$6:$AN$25) -> 0 | BA11: =IF(SUM($AY$6:$AY$11)>0,AY11,AZ11) -> 0 | BC11: =SUMPRODUCT((Lançamentos!$C$3:$N$3<=$AD$3)*(Lançamentos!$C$24:$N$24>0)) -> 9 | BE11: =AE11 -> Jun | BF11: =IF(Faturamento!H17=0,"",Faturamento!H16) | BG11: =IF(Lançamentos!H24=0,"",Lançamentos!H23) -> 42950.282 | BH11: =IF(OR(BF11="",BG11=""),"",BF11-BG11)
AE12: Jul | AF12: =Orçado!I23 -> 46707.722 | AG12: =IF(AI12=0,"",IF(AND($U$3<>"Ano",7=$AD$1),"",Lançamentos!I23)) -> 46707.722 | AH12: =IF(AND($U$3<>"Ano",7=$AD$1,AI12=1),Lançamentos!I23,"") | AI12: =IF(Lançamentos!I24>0,1,0) -> 1 | AL12: =Lançamentos!A11 -> Controle de Ponto | AM12: =Lançamentos!B11 -> Pessoal | AN12: =IF(AL12="","",SUMPRODUCT((Lançamentos!$C$3:$N$3>=$AD$1)*(Lançamentos!$C$3:$N$3<=$AD$3)*Orçado!$C11:$N11)) -> 944 | AO12: =IF(AL12="","",SUMPRODUCT((Lançamentos!$C$3:$N$3>=$AD$1)*(Lançamentos!$C$3:$N$3<=$AD$3)*Lançamentos!$C11:$N11)) -> 944 | AP12: =IF(AL12="","",IF($BC$8>0,SUMPRODUCT((Lançamentos!$C$3:$N$3>=$AD$1)*(Lançamentos!$C$3:$N$3<=$AD$3)*(Lançamentos!$C$24:$N$24>0)*Orçado!$C11:$N11),AN12)) -> 944 | AQ12: =IF(AL12="","",AO12+AP12/1000000+ROW()/1000000000) -> 944.00094 | AS12: =IFERROR(MATCH(LARGE($AQ$6:$AQ$25,7),$AQ$6:$AQ$25,0),"") -> 18 | AT12: =IF(AS12="","",INDEX($AL$6:$AL$25,AS12)) -> Seguro do Caminhão | AU12: =IF(AS12="","",INDEX($AO$6:$AO$25,AS12)) -> 3714.4933 | AV12: =IF(AS12="","",INDEX($AP$6:$AP$25,AS12)) -> 3714.4933 | BC12: =SUMIF($AM$6:$AM$25,"Pessoal",$AO$6:$AO$25) -> 115134.48 | BE12: =AE12 -> Jul | BF12: =IF(Faturamento!I17=0,"",Faturamento!I16) | BG12: =IF(Lançamentos!I24=0,"",Lançamentos!I23) -> 46707.722 | BH12: =IF(OR(BF12="",BG12=""),"",BF12-BG12)
B13: Orçado x Realizado por mês | R13: ="Por categoria · "&$BC$14 -> Por categoria · Ano 2026 | AE13: Ago | AF13: =Orçado!J23 -> 35256.052 | AG13: =IF(AI13=0,"",IF(AND($U$3<>"Ano",8=$AD$1),"",Lançamentos!J23)) -> 35256.052 | AH13: =IF(AND($U$3<>"Ano",8=$AD$1,AI13=1),Lançamentos!J23,"") | AI13: =IF(Lançamentos!J24>0,1,0) -> 1 | AL13: =Lançamentos!A12 -> Extintores | AM13: =Lançamentos!B12 -> Manutenção | AN13: =IF(AL13="","",SUMPRODUCT((Lançamentos!$C$3:$N$3>=$AD$1)*(Lançamentos!$C$3:$N$3<=$AD$3)*Orçado!$C12:$N12)) -> 570 | AO13: =IF(AL13="","",SUMPRODUCT((Lançamentos!$C$3:$N$3>=$AD$1)*(Lançamentos!$C$3:$N$3<=$AD$3)*Lançamentos!$C12:$N12)) -> 570 | AP13: =IF(AL13="","",IF($BC$8>0,SUMPRODUCT((Lançamentos!$C$3:$N$3>=$AD$1)*(Lançamentos!$C$3:$N$3<=$AD$3)*(Lançamentos!$C$24:$N$24>0)*Orçado!$C12:$N12),AN13)) -> 570 | AQ13: =IF(AL13="","",AO13+AP13/1000000+ROW()/1000000000) -> 570.00057 | AS13: =IFERROR(MATCH(LARGE($AQ$6:$AQ$25,8),$AQ$6:$AQ$25,0),"") -> 4 | AT13: =IF(AS13="","",INDEX($AL$6:$AL$25,AS13)) -> Segurança Emive | AU13: =IF(AS13="","",INDEX($AO$6:$AO$25,AS13)) -> 3072 | AV13: =IF(AS13="","",INDEX($AP$6:$AP$25,AS13)) -> 3072 | BC13: =SUMIF($AM$6:$AM$25,"Pessoal",$AN$6:$AN$25) -> 115134.48 | BE13: =AE13 -> Ago | BF13: =IF(Faturamento!J17=0,"",Faturamento!J16) | BG13: =IF(Lançamentos!J24=0,"",Lançamentos!J23) -> 35256.052 | BH13: =IF(OR(BF13="",BG13=""),"",BF13-BG13)
AE14: Set | AF14: =Orçado!K23 -> 0 | AG14: =IF(AI14=0,"",IF(AND($U$3<>"Ano",9=$AD$1),"",Lançamentos!K23)) -> 3379.49 | AH14: =IF(AND($U$3<>"Ano",9=$AD$1,AI14=1),Lançamentos!K23,"") | AI14: =IF(Lançamentos!K24>0,1,0) -> 1 | AL14: =Lançamentos!A13 -> Internet | AM14: =Lançamentos!B13 -> Utilidades | AN14: =IF(AL14="","",SUMPRODUCT((Lançamentos!$C$3:$N$3>=$AD$1)*(Lançamentos!$C$3:$N$3<=$AD$3)*Orçado!$C13:$N13)) -> 1341.68 | AO14: =IF(AL14="","",SUMPRODUCT((Lançamentos!$C$3:$N$3>=$AD$1)*(Lançamentos!$C$3:$N$3<=$AD$3)*Lançamentos!$C13:$N13)) -> 1341.68 | AP14: =IF(AL14="","",IF($BC$8>0,SUMPRODUCT((Lançamentos!$C$3:$N$3>=$AD$1)*(Lançamentos!$C$3:$N$3<=$AD$3)*(Lançamentos!$C$24:$N$24>0)*Orçado!$C13:$N13),AN14)) -> 1341.68 | AQ14: =IF(AL14="","",AO14+AP14/1000000+ROW()/1000000000) -> 1341.6813 | AS14: =IFERROR(MATCH(LARGE($AQ$6:$AQ$25,9),$AQ$6:$AQ$25,0),"") -> 6 | AT14: =IF(AS14="","",INDEX($AL$6:$AL$25,AS14)) -> IPTU | AU14: =IF(AS14="","",INDEX($AO$6:$AO$25,AS14)) -> 2569.27 | AV14: =IF(AS14="","",INDEX($AP$6:$AP$25,AS14)) -> 2569.27 | BC14: =IF($U$3="Ano","Ano "&Cadastro!$G$2,$U$3&"/"&Cadastro!$G$2) -> Ano 2026 | BE14: =AE14 -> Set | BF14: =IF(Faturamento!K17=0,"",Faturamento!K16) | BG14: =IF(Lançamentos!K24=0,"",Lançamentos!K23) -> 3379.49 | BH14: =IF(OR(BF14="",BG14=""),"",BF14-BG14)
AE15: Out | AF15: =Orçado!L23 -> 0 | AG15: =IF(AI15=0,"",IF(AND($U$3<>"Ano",10=$AD$1),"",Lançamentos!L23)) | AH15: =IF(AND($U$3<>"Ano",10=$AD$1,AI15=1),Lançamentos!L23,"") | AI15: =IF(Lançamentos!L24>0,1,0) -> 0 | AL15: =Lançamentos!A14 -> Funcionários | AM15: =Lançamentos!B14 -> Pessoal | AN15: =IF(AL15="","",SUMPRODUCT((Lançamentos!$C$3:$N$3>=$AD$1)*(Lançamentos!$C$3:$N$3<=$AD$3)*Orçado!$C14:$N14)) -> 113702.48 | AO15: =IF(AL15="","",SUMPRODUCT((Lançamentos!$C$3:$N$3>=$AD$1)*(Lançamentos!$C$3:$N$3<=$AD$3)*Lançamentos!$C14:$N14)) -> 113702.48 | AP15: =IF(AL15="","",IF($BC$8>0,SUMPRODUCT((Lançamentos!$C$3:$N$3>=$AD$1)*(Lançamentos!$C$3:$N$3<=$AD$3)*(Lançamentos!$C$24:$N$24>0)*Orçado!$C14:$N14),AN15)) -> 113702.48 | AQ15: =IF(AL15="","",AO15+AP15/1000000+ROW()/1000000000) -> 113702.59 | AS15: =IFERROR(MATCH(LARGE($AQ$6:$AQ$25,10),$AQ$6:$AQ$25,0),"") -> 3 | AT15: =IF(AS15="","",INDEX($AL$6:$AL$25,AS15)) -> Seguro galpão | AU15: =IF(AS15="","",INDEX($AO$6:$AO$25,AS15)) -> 2569.27 | AV15: =IF(AS15="","",INDEX($AP$6:$AP$25,AS15)) -> 2569.27 | BC15: =IF(BC8>0,BC8,BC7) -> 315259.37 | BE15: =AE15 -> Out | BF15: =IF(Faturamento!L17=0,"",Faturamento!L16) | BG15: =IF(Lançamentos!L24=0,"",Lançamentos!L23) | BH15: =IF(OR(BF15="",BG15=""),"",BF15-BG15)
AE16: Nov | AF16: =Orçado!M23 -> 0 | AG16: =IF(AI16=0,"",IF(AND($U$3<>"Ano",11=$AD$1),"",Lançamentos!M23)) | AH16: =IF(AND($U$3<>"Ano",11=$AD$1,AI16=1),Lançamentos!M23,"") | AI16: =IF(Lançamentos!M24>0,1,0) -> 0 | AL16: ="" | AM16: ="" | AN16: ="" | AO16: ="" | AP16: ="" | AQ16: =IF(AL16="","",AO16+AP16/1000000+ROW()/1000000000) | BE16: =AE16 -> Nov | BF16: =IF(Faturamento!M17=0,"",Faturamento!M16) | BG16: =IF(Lançamentos!M24=0,"",Lançamentos!M23) | BH16: =IF(OR(BF16="",BG16=""),"",BF16-BG16)
AE17: Dez | AF17: =Orçado!N23 -> 0 | AG17: =IF(AI17=0,"",IF(AND($U$3<>"Ano",12=$AD$1),"",Lançamentos!N23)) | AH17: =IF(AND($U$3<>"Ano",12=$AD$1,AI17=1),Lançamentos!N23,"") | AI17: =IF(Lançamentos!N24>0,1,0) -> 0 | AL17: ="" | AM17: ="" | AN17: ="" | AO17: ="" | AP17: ="" | AQ17: =IF(AL17="","",AO17+AP17/1000000+ROW()/1000000000) | BC17: =SUMPRODUCT((Faturamento!$C$3:$N$3>=$AD$1)*(Faturamento!$C$3:$N$3<=$AD$3)*Faturamento!$C$16:$N$16) -> 0 | BE17: =AE17 -> Dez | BF17: =IF(Faturamento!N17=0,"",Faturamento!N16) | BG17: =IF(Lançamentos!N24=0,"",Lançamentos!N23) | BH17: =IF(OR(BF17="",BG17=""),"",BF17-BG17)
AL18: ="" | AM18: ="" | AN18: ="" | AO18: ="" | AP18: ="" | AQ18: =IF(AL18="","",AO18+AP18/1000000+ROW()/1000000000) | BC18: =SUM(Faturamento!$C$16:$N$16) -> 0
AL19: =Lançamentos!A15 -> Combustivel | AM19: =Lançamentos!B15 -> Veiculo | AN19: =IF(AL19="","",SUMPRODUCT((Lançamentos!$C$3:$N$3>=$AD$1)*(Lançamentos!$C$3:$N$3<=$AD$3)*Orçado!$C15:$N15)) -> 30733.02 | AO19: =IF(AL19="","",SUMPRODUCT((Lançamentos!$C$3:$N$3>=$AD$1)*(Lançamentos!$C$3:$N$3<=$AD$3)*Lançamentos!$C15:$N15)) -> 30733.02 | AP19: =IF(AL19="","",IF($BC$8>0,SUMPRODUCT((Lançamentos!$C$3:$N$3>=$AD$1)*(Lançamentos!$C$3:$N$3<=$AD$3)*(Lançamentos!$C$24:$N$24>0)*Orçado!$C15:$N15),AN19)) -> 30733.02 | AQ19: =IF(AL19="","",AO19+AP19/1000000+ROW()/1000000000) -> 30733.051 | BC19: =SUM(Faturamento!$C$17:$N$17) -> 0
AL20: =Lançamentos!A16 -> Manutenção Veicular (peças, servico, revisao, licenciamento) | AM20: =Lançamentos!B16 -> Manutenção | AN20: =IF(AL20="","",SUMPRODUCT((Lançamentos!$C$3:$N$3>=$AD$1)*(Lançamentos!$C$3:$N$3<=$AD$3)*Orçado!$C16:$N16)) -> 9533 | AO20: =IF(AL20="","",SUMPRODUCT((Lançamentos!$C$3:$N$3>=$AD$1)*(Lançamentos!$C$3:$N$3<=$AD$3)*Lançamentos!$C16:$N16)) -> 10623 | AP20: =IF(AL20="","",IF($BC$8>0,SUMPRODUCT((Lançamentos!$C$3:$N$3>=$AD$1)*(Lançamentos!$C$3:$N$3<=$AD$3)*(Lançamentos!$C$24:$N$24>0)*Orçado!$C16:$N16),AN20)) -> 9533 | AQ20: =IF(AL20="","",AO20+AP20/1000000+ROW()/1000000000) -> 10623.01 | BC20: =SUM(Lançamentos!$C$23:$N$23) -> 319728.86
AL21: =Lançamentos!A17 -> Tubete | AM21: =Lançamentos!B17 -> Insumo | AN21: =IF(AL21="","",SUMPRODUCT((Lançamentos!$C$3:$N$3>=$AD$1)*(Lançamentos!$C$3:$N$3<=$AD$3)*Orçado!$C17:$N17)) -> 112281.2 | AO21: =IF(AL21="","",SUMPRODUCT((Lançamentos!$C$3:$N$3>=$AD$1)*(Lançamentos!$C$3:$N$3<=$AD$3)*Lançamentos!$C17:$N17)) -> 112281.2 | AP21: =IF(AL21="","",IF($BC$8>0,SUMPRODUCT((Lançamentos!$C$3:$N$3>=$AD$1)*(Lançamentos!$C$3:$N$3<=$AD$3)*(Lançamentos!$C$24:$N$24>0)*Orçado!$C17:$N17),AN21)) -> 112281.2 | AQ21: =IF(AL21="","",AO21+AP21/1000000+ROW()/1000000000) -> 112281.31
AL22: =Lançamentos!A18 -> Manutenção Predial | AM22: =Lançamentos!B18 -> Manutenção | AN22: =IF(AL22="","",SUMPRODUCT((Lançamentos!$C$3:$N$3>=$AD$1)*(Lançamentos!$C$3:$N$3<=$AD$3)*Orçado!$C18:$N18)) -> 4198 | AO22: =IF(AL22="","",SUMPRODUCT((Lançamentos!$C$3:$N$3>=$AD$1)*(Lançamentos!$C$3:$N$3<=$AD$3)*Lançamentos!$C18:$N18)) -> 4198 | AP22: =IF(AL22="","",IF($BC$8>0,SUMPRODUCT((Lançamentos!$C$3:$N$3>=$AD$1)*(Lançamentos!$C$3:$N$3<=$AD$3)*(Lançamentos!$C$24:$N$24>0)*Orçado!$C18:$N18),AN22)) -> 4198 | AQ22: =IF(AL22="","",AO22+AP22/1000000+ROW()/1000000000) -> 4198.0042
AL23: =Lançamentos!A19 -> Seguro do Caminhão | AM23: =Lançamentos!B19 -> Veiculo | AN23: =IF(AL23="","",SUMPRODUCT((Lançamentos!$C$3:$N$3>=$AD$1)*(Lançamentos!$C$3:$N$3<=$AD$3)*Orçado!$C19:$N19)) -> 3714.4933 | AO23: =IF(AL23="","",SUMPRODUCT((Lançamentos!$C$3:$N$3>=$AD$1)*(Lançamentos!$C$3:$N$3<=$AD$3)*Lançamentos!$C19:$N19)) -> 3714.4933 | AP23: =IF(AL23="","",IF($BC$8>0,SUMPRODUCT((Lançamentos!$C$3:$N$3>=$AD$1)*(Lançamentos!$C$3:$N$3<=$AD$3)*(Lançamentos!$C$24:$N$24>0)*Orçado!$C19:$N19),AN23)) -> 3714.4933 | AQ23: =IF(AL23="","",AO23+AP23/1000000+ROW()/1000000000) -> 3714.497
AL24: =Lançamentos!A20 -> Parcela Caminhão | AM24: =Lançamentos!B20 -> Veiculo | AN24: =IF(AL24="","",SUMPRODUCT((Lançamentos!$C$3:$N$3>=$AD$1)*(Lançamentos!$C$3:$N$3<=$AD$3)*Orçado!$C20:$N20)) -> 27035.92 | AO24: =IF(AL24="","",SUMPRODUCT((Lançamentos!$C$3:$N$3>=$AD$1)*(Lançamentos!$C$3:$N$3<=$AD$3)*Lançamentos!$C20:$N20)) -> 30415.41 | AP24: =IF(AL24="","",IF($BC$8>0,SUMPRODUCT((Lançamentos!$C$3:$N$3>=$AD$1)*(Lançamentos!$C$3:$N$3<=$AD$3)*(Lançamentos!$C$24:$N$24>0)*Orçado!$C20:$N20),AN24)) -> 27035.92 | AQ24: =IF(AL24="","",AO24+AP24/1000000+ROW()/1000000000) -> 30415.437
AL25: =Lançamentos!A21 -> Despesas Pessoal (EPI, Farda e Ferramentas, Diaristas) | AM25: =Lançamentos!B21 -> Pessoal | AN25: =IF(AL25="","",SUMPRODUCT((Lançamentos!$C$3:$N$3>=$AD$1)*(Lançamentos!$C$3:$N$3<=$AD$3)*Orçado!$C21:$N21)) -> 488 | AO25: =IF(AL25="","",SUMPRODUCT((Lançamentos!$C$3:$N$3>=$AD$1)*(Lançamentos!$C$3:$N$3<=$AD$3)*Lançamentos!$C21:$N21)) -> 488 | AP25: =IF(AL25="","",IF($BC$8>0,SUMPRODUCT((Lançamentos!$C$3:$N$3>=$AD$1)*(Lançamentos!$C$3:$N$3<=$AD$3)*(Lançamentos!$C$24:$N$24>0)*Orçado!$C21:$N21),AN25)) -> 488 | AQ25: =IF(AL25="","",AO25+AP25/1000000+ROW()/1000000000) -> 488.00049
B30: ="Por despesa · "&$BC$14 -> Por despesa · Ano 2026 | O30: ="Detalhe · "&$BC$14 -> Detalhe · Ano 2026
O32: Despesa | T32: Orçado | W32: Realizado | Z32: Var.
O33: =AT6 -> Funcionários | T33: =IF(AT6="","",AV6) -> 113702.48 | W33: =IF(AT6="","",AU6) -> 113702.48 | Z33: =IF(OR(AT6="",N(AU6)=0,N(AV6)=0),"",AU6/AV6-1) -> 0
O34: =AT7 -> Tubete | T34: =IF(AT7="","",AV7) -> 112281.2 | W34: =IF(AT7="","",AU7) -> 112281.2 | Z34: =IF(OR(AT7="",N(AU7)=0,N(AV7)=0),"",AU7/AV7-1) -> 0
O35: =AT8 -> Combustivel | T35: =IF(AT8="","",AV8) -> 30733.02 | W35: =IF(AT8="","",AU8) -> 30733.02 | Z35: =IF(OR(AT8="",N(AU8)=0,N(AV8)=0),"",AU8/AV8-1) -> 0
O36: =AT9 -> Parcela Caminhão | T36: =IF(AT9="","",AV9) -> 27035.92 | W36: =IF(AT9="","",AU9) -> 30415.41 | Z36: =IF(OR(AT9="",N(AU9)=0,N(AV9)=0),"",AU9/AV9-1) -> 0.125
O37: =AT10 -> Manutenção Veicular (peças, servico, revisao, licenciamento) | T37: =IF(AT10="","",AV10) -> 9533 | W37: =IF(AT10="","",AU10) -> 10623 | Z37: =IF(OR(AT10="",N(AU10)=0,N(AV10)=0),"",AU10/AV10-1) -> 0.11433966
O38: =AT11 -> Manutenção Predial | T38: =IF(AT11="","",AV11) -> 4198 | W38: =IF(AT11="","",AU11) -> 4198 | Z38: =IF(OR(AT11="",N(AU11)=0,N(AV11)=0),"",AU11/AV11-1) -> 0
O39: =AT12 -> Seguro do Caminhão | T39: =IF(AT12="","",AV12) -> 3714.4933 | W39: =IF(AT12="","",AU12) -> 3714.4933 | Z39: =IF(OR(AT12="",N(AU12)=0,N(AV12)=0),"",AU12/AV12-1) -> 0
O40: =AT13 -> Segurança Emive | T40: =IF(AT13="","",AV13) -> 3072 | W40: =IF(AT13="","",AU13) -> 3072 | Z40: =IF(OR(AT13="",N(AU13)=0,N(AV13)=0),"",AU13/AV13-1) -> 0
O41: =AT14 -> IPTU | T41: =IF(AT14="","",AV14) -> 2569.27 | W41: =IF(AT14="","",AU14) -> 2569.27 | Z41: =IF(OR(AT14="",N(AU14)=0,N(AV14)=0),"",AU14/AV14-1) -> 0
O42: =AT15 -> Seguro galpão | T42: =IF(AT15="","",AV15) -> 2569.27 | W42: =IF(AT15="","",AU15) -> 2569.27 | Z42: =IF(OR(AT15="",N(AU15)=0,N(AV15)=0),"",AU15/AV15-1) -> 0
O44: Total | T44: =BC15 -> 315259.37 | W44: =BC6 -> 319728.86 | Z44: =IF(OR(BC6=0,BC15=0),"",BC6/BC15-1) -> 0.014177184
B47: ="Receitas x Despesas · "&$BC$14 -> Receitas x Despesas · Ano 2026
B49: Faturamento · período | F49: Despesas · período | J49: Resultado (Rec − Desp) | N49: Margem líquida | R49: Faturam. médio/mês | W49: Despesa média/mês
B50: =BC17 -> 0 | F50: =BC6 -> 319728.86 | J50: =BC17-BC6 -> -319728.86 | N50: =IF(BC17=0,0,(BC17-BC6)/BC17) -> 0 | R50: =IF(BC19=0,0,BC18/BC19) -> 0 | W50: =BC20/12 -> 26644.072
...

Sheet Lançamentos
A1: LANÇAMENTOS MENSAIS — VALORES REALIZADOS (PAGOS)
A2: Preencha nas células amarelas o valor efetivamente pago em cada mês (ex.: Energia em Jan → 152,40). Deixe em branco o que ainda não foi lançado; se não houve pagamento no mês, digite 0.
A3: nº do mês → | C3: 1 | D3: 2 | E3: 3 | F3: 4 | G3: 5 | H3: 6 | I3: 7 | J3: 8 | K3: 9 | L3: 10 | M3: 11 | N3: 12
A4: Despesa | B4: Categoria | C4: Jan | D4: Fev | E4: Mar | F4: Abr | G4: Mai | H4: Jun | I4: Jul | J4: Ago | K4: Set | L4: Out | M4: Nov | N4: Dez | O4: Total ano | P4: Média mensal
A5: =IF(Cadastro!B5="","",Cadastro!B5) -> Água | B5: =IF(Cadastro!C5="","",Cadastro!C5) -> Utilidades | C5: =IF($A5="","",IF(MOD(C$3-N(Cadastro!$F5),Cadastro!$G5)=0,Cadastro!$D5,0)) -> 93.19 | D5: =IF($A5="","",IF(MOD(D$3-N(Cadastro!$F5),Cadastro!$G5)=0,Cadastro!$D5,0)) -> 93.19 | E5: =IF($A5="","",IF(MOD(E$3-N(Cadastro!$F5),Cadastro!$G5)=0,Cadastro!$D5,0)) -> 93.19 | F5: =IF($A5="","",IF(MOD(F$3-N(Cadastro!$F5),Cadastro!$G5)=0,Cadastro!$D5,0)) -> 93.19 | G5: =IF($A5="","",IF(MOD(G$3-N(Cadastro!$F5),Cadastro!$G5)=0,Cadastro!$D5,0)) -> 93.19 | H5: =IF($A5="","",IF(MOD(H$3-N(Cadastro!$F5),Cadastro!$G5)=0,Cadastro!$D5,0)) -> 93.19 | I5: =IF($A5="","",IF(MOD(I$3-N(Cadastro!$F5),Cadastro!$G5)=0,Cadastro!$D5,0)) -> 93.19 | J5: =IF($A5="","",IF(MOD(J$3-N(Cadastro!$F5),Cadastro!$G5)=0,Cadastro!$D5,0)) -> 93.19 | O5: =IF($A5="","",SUM(C5:N5)) -> 745.52 | P5: =IF(OR($A5="",COUNT(C5:N5)=0),"",AVERAGE(C5:N5)) -> 93.19
A6: =IF(Cadastro!B6="","",Cadastro!B6) -> Energia | B6: =IF(Cadastro!C6="","",Cadastro!C6) -> Utilidades | C6: =IF($A6="","",IF(MOD(C$3-N(Cadastro!$F6),Cadastro!$G6)=0,Cadastro!$D6,0)) -> 145.19 | D6: =IF($A6="","",IF(MOD(D$3-N(Cadastro!$F6),Cadastro!$G6)=0,Cadastro!$D6,0)) -> 145.19 | E6: =IF($A6="","",IF(MOD(E$3-N(Cadastro!$F6),Cadastro!$G6)=0,Cadastro!$D6,0)) -> 145.19 | F6: =IF($A6="","",IF(MOD(F$3-N(Cadastro!$F6),Cadastro!$G6)=0,Cadastro!$D6,0)) -> 145.19 | G6: =IF($A6="","",IF(MOD(G$3-N(Cadastro!$F6),Cadastro!$G6)=0,Cadastro!$D6,0)) -> 145.19 | H6: =IF($A6="","",IF(MOD(H$3-N(Cadastro!$F6),Cadastro!$G6)=0,Cadastro!$D6,0)) -> 145.19 | I6: =IF($A6="","",IF(MOD(I$3-N(Cadastro!$F6),Cadastro!$G6)=0,Cadastro!$D6,0)) -> 145.19 | J6: =IF($A6="","",IF(MOD(J$3-N(Cadastro!$F6),Cadastro!$G6)=0,Cadastro!$D6,0)) -> 145.19 | O6: =IF($A6="","",SUM(C6:N6)) -> 1161.52 | P6: =IF(OR($A6="",COUNT(C6:N6)=0),"",AVERAGE(C6:N6)) -> 145.19
A7: =IF(Cadastro!B7="","",Cadastro!B7) -> Seguro galpão | B7: =IF(Cadastro!C7="","",Cadastro!C7) -> Seguros e Segurança | C7: 2569.27 | D7: =IF($A7="","",IF(MOD(D$3-N(Cadastro!$F7),Cadastro!$G7)=0,Cadastro!$D7,0)) -> 0 | F7: =IF($A7="","",IF(MOD(F$3-N(Cadastro!$F7),Cadastro!$G7)=0,Cadastro!$D7,0)) -> 0 | G7: =IF($A7="","",IF(MOD(G$3-N(Cadastro!$F7),Cadastro!$G7)=0,Cadastro!$D7,0)) -> 0 | H7: =IF($A7="","",IF(MOD(H$3-N(Cadastro!$F7),Cadastro!$G7)=0,Cadastro!$D7,0)) -> 0 | I7: =IF($A7="","",IF(MOD(I$3-N(Cadastro!$F7),Cadastro!$G7)=0,Cadastro!$D7,0)) -> 0 | J7: =IF($A7="","",IF(MOD(J$3-N(Cadastro!$F7),Cadastro!$G7)=0,Cadastro!$D7,0)) -> 0 | O7: =IF($A7="","",SUM(C7:N7)) -> 2569.27 | P7: =IF(OR($A7="",COUNT(C7:N7)=0),"",AVERAGE(C7:N7)) -> 367.03857
A8: =IF(Cadastro!B8="","",Cadastro!B8) -> Segurança Emive | B8: =IF(Cadastro!C8="","",Cadastro!C8) -> Seguros e Segurança | C8: =IF($A8="","",IF(MOD(C$3-N(Cadastro!$F8),Cadastro!$G8)=0,Cadastro!$D8,0)) -> 384 | D8: =IF($A8="","",IF(MOD(D$3-N(Cadastro!$F8),Cadastro!$G8)=0,Cadastro!$D8,0)) -> 384 | E8: =IF($A8="","",IF(MOD(E$3-N(Cadastro!$F8),Cadastro!$G8)=0,Cadastro!$D8,0)) -> 384 | F8: =IF($A8="","",IF(MOD(F$3-N(Cadastro!$F8),Cadastro!$G8)=0,Cadastro!$D8,0)) -> 384 | G8: =IF($A8="","",IF(MOD(G$3-N(Cadastro!$F8),Cadastro!$G8)=0,Cadastro!$D8,0)) -> 384 | H8: =IF($A8="","",IF(MOD(H$3-N(Cadastro!$F8),Cadastro!$G8)=0,Cadastro!$D8,0)) -> 384 | I8: =IF($A8="","",IF(MOD(I$3-N(Cadastro!$F8),Cadastro!$G8)=0,Cadastro!$D8,0)) -> 384 | J8: =IF($A8="","",IF(MOD(J$3-N(Cadastro!$F8),Cadastro!$G8)=0,Cadastro!$D8,0)) -> 384 | O8: =IF($A8="","",SUM(C8:N8)) -> 3072 | P8: =IF(OR($A8="",COUNT(C8:N8)=0),"",AVERAGE(C8:N8)) -> 384
A9: =IF(Cadastro!B9="","",Cadastro!B9) -> Dedetização | B9: =IF(Cadastro!C9="","",Cadastro!C9) -> Manutenção | C9: =IF($A9="","",IF(MOD(C$3-N(Cadastro!$F9),Cadastro!$G9)=0,Cadastro!$D9,0)) -> 300 | D9: =IF($A9="","",IF(MOD(D$3-N(Cadastro!$F9),Cadastro!$G9)=0,Cadastro!$D9,0)) -> 0 | E9: =IF($A9="","",IF(MOD(E$3-N(Cadastro!$F9),Cadastro!$G9)=0,Cadastro!$D9,0)) -> 0 | F9: =IF($A9="","",IF(MOD(F$3-N(Cadastro!$F9),Cadastro!$G9)=0,Cadastro!$D9,0)) -> 0 | G9: =IF($A9="","",IF(MOD(G$3-N(Cadastro!$F9),Cadastro!$G9)=0,Cadastro!$D9,0)) -> 0 | H9: =IF($A9="","",IF(MOD(H$3-N(Cadastro!$F9),Cadastro!$G9)=0,Cadastro!$D9,0)) -> 0 | I9: =IF($A9="","",IF(MOD(I$3-N(Cadastro!$F9),Cadastro!$G9)=0,Cadastro!$D9,0)) -> 300 | J9: =IF($A9="","",IF(MOD(J$3-N(Cadastro!$F9),Cadastro!$G9)=0,Cadastro!$D9,0)) -> 0 | O9: =IF($A9="","",SUM(C9:N9)) -> 600 | P9: =IF(OR($A9="",COUNT(C9:N9)=0),"",AVERAGE(C9:N9)) -> 75
A10: =IF(Cadastro!B10="","",Cadastro!B10) -> IPTU | B10: =IF(Cadastro!C10="","",Cadastro!C10) -> Impostos e Taxas | C10: =IF($A10="","",IF(MOD(C$3-N(Cadastro!$F10),Cadastro!$G10)=0,Cadastro!$D10,0)) -> 0 | D10: =IF($A10="","",IF(MOD(D$3-N(Cadastro!$F10),Cadastro!$G10)=0,Cadastro!$D10,0)) -> 2569.27 | E10: =IF($A10="","",IF(MOD(E$3-N(Cadastro!$F10),Cadastro!$G10)=0,Cadastro!$D10,0)) -> 0 | F10: =IF($A10="","",IF(MOD(F$3-N(Cadastro!$F10),Cadastro!$G10)=0,Cadastro!$D10,0)) -> 0 | G10: =IF($A10="","",IF(MOD(G$3-N(Cadastro!$F10),Cadastro!$G10)=0,Cadastro!$D10,0)) -> 0 | H10: =IF($A10="","",IF(MOD(H$3-N(Cadastro!$F10),Cadastro!$G10)=0,Cadastro!$D10,0)) -> 0 | I10: =IF($A10="","",IF(MOD(I$3-N(Cadastro!$F10),Cadastro!$G10)=0,Cadastro!$D10,0)) -> 0 | J10: =IF($A10="","",IF(MOD(J$3-N(Cadastro!$F10),Cadastro!$G10)=0,Cadastro!$D10,0)) -> 0 | O10: =IF($A10="","",SUM(C10:N10)) -> 2569.27 | P10: =IF(OR($A10="",COUNT(C10:N10)=0),"",AVERAGE(C10:N10)) -> 321.15875
A11: =IF(Cadastro!B11="","",Cadastro!B11) -> Controle de Ponto | B11: =IF(Cadastro!C11="","",Cadastro!C11) -> Pessoal | C11: =IF($A11="","",IF(MOD(C$3-N(Cadastro!$F11),Cadastro!$G11)=0,Cadastro!$D11,0)) -> 118 | D11: =IF($A11="","",IF(MOD(D$3-N(Cadastro!$F11),Cadastro!$G11)=0,Cadastro!$D11,0)) -> 118 | E11: =IF($A11="","",IF(MOD(E$3-N(Cadastro!$F11),Cadastro!$G11)=0,Cadastro!$D11,0)) -> 118 | F11: =IF($A11="","",IF(MOD(F$3-N(Cadastro!$F11),Cadastro!$G11)=0,Cadastro!$D11,0)) -> 118 | G11: =IF($A11="","",IF(MOD(G$3-N(Cadastro!$F11),Cadastro!$G11)=0,Cadastro!$D11,0)) -> 118 | H11: =IF($A11="","",IF(MOD(H$3-N(Cadastro!$F11),Cadastro!$G11)=0,Cadastro!$D11,0)) -> 118 | I11: =IF($A11="","",IF(MOD(I$3-N(Cadastro!$F11),Cadastro!$G11)=0,Cadastro!$D11,0)) -> 118 | J11: =IF($A11="","",IF(MOD(J$3-N(Cadastro!$F11),Cadastro!$G11)=0,Cadastro!$D11,0)) -> 118 | O11: =IF($A11="","",SUM(C11:N11)) -> 944 | P11: =IF(OR($A11="",COUNT(C11:N11)=0),"",AVERAGE(C11:N11)) -> 118
A12: =IF(Cadastro!B12="","",Cadastro!B12) -> Extintores | B12: =IF(Cadastro!C12="","",Cadastro!C12) -> Manutenção | C12: =IF($A12="","",IF(MOD(C$3-N(Cadastro!$F12),Cadastro!$G12)=0,Cadastro!$D12,0)) -> 0 | D12: =IF($A12="","",IF(MOD(D$3-N(Cadastro!$F12),Cadastro!$G12)=0,Cadastro!$D12,0)) -> 0 | E12: =IF($A12="","",IF(MOD(E$3-N(Cadastro!$F12),Cadastro!$G12)=0,Cadastro!$D12,0)) -> 0 | F12: =IF($A12="","",IF(MOD(F$3-N(Cadastro!$F12),Cadastro!$G12)=0,Cadastro!$D12,0)) -> 0 | G12: =IF($A12="","",IF(MOD(G$3-N(Cadastro!$F12),Cadastro!$G12)=0,Cadastro!$D12,0)) -> 0 | H12: =IF($A12="","",IF(MOD(H$3-N(Cadastro!$F12),Cadastro!$G12)=0,Cadastro!$D12,0)) -> 570 | I12: =IF($A12="","",IF(MOD(I$3-N(Cadastro!$F12),Cadastro!$G12)=0,Cadastro!$D12,0)) -> 0 | J12: =IF($A12="","",IF(MOD(J$3-N(Cadastro!$F12),Cadastro!$G12)=0,Cadastro!$D12,0)) -> 0 | O12: =IF($A12="","",SUM(C12:N12)) -> 570 | P12: =IF(OR($A12="",COUNT(C12:N12)=0),"",AVERAGE(C12:N12)) -> 71.25
A13: =IF(Cadastro!B13="","",Cadastro!B13) -> Internet | B13: =IF(Cadastro!C13="","",Cadastro!C13) -> Utilidades | C13: =IF($A13="","",IF(MOD(C$3-N(Cadastro!$F13),Cadastro!$G13)=0,Cadastro!$D13,0)) -> 167.71 | D13: =IF($A13="","",IF(MOD(D$3-N(Cadastro!$F13),Cadastro!$G13)=0,Cadastro!$D13,0)) -> 167.71 | E13: =IF($A13="","",IF(MOD(E$3-N(Cadastro!$F13),Cadastro!$G13)=0,Cadastro!$D13,0)) -> 167.71 | F13: =IF($A13="","",IF(MOD(F$3-N(Cadastro!$F13),Cadastro!$G13)=0,Cadastro!$D13,0)) -> 167.71 | G13: =IF($A13="","",IF(MOD(G$3-N(Cadastro!$F13),Cadastro!$G13)=0,Cadastro!$D13,0)) -> 167.71 | H13: =IF($A13="","",IF(MOD(H$3-N(Cadastro!$F13),Cadastro!$G13)=0,Cadastro!$D13,0)) -> 167.71 | I13: =IF($A13="","",IF(MOD(I$3-N(Cadastro!$F13),Cadastro!$G13)=0,Cadastro!$D13,0)) -> 167.71 | J13: =IF($A13="","",IF(MOD(J$3-N(Cadastro!$F13),Cadastro!$G13)=0,Cadastro!$D13,0)) -> 167.71 | O13: =IF($A13="","",SUM(C13:N13)) -> 1341.68 | P13: =IF(OR($A13="",COUNT(C13:N13)=0),"",AVERAGE(C13:N13)) -> 167.71
A14: =IF(Cadastro!B14="","",Cadastro!B14) -> Funcionários | B14: =IF(Cadastro!C14="","",Cadastro!C14) -> Pessoal | C14: =IF($A14="","",IF(MOD(C$3-N(Cadastro!$F14),Cadastro!$G14)=0,Cadastro!$D14,0)) -> 14212.81 | D14: =IF($A14="","",IF(MOD(D$3-N(Cadastro!$F14),Cadastro!$G14)=0,Cadastro!$D14,0)) -> 14212.81 | E14: =IF($A14="","",IF(MOD(E$3-N(Cadastro!$F14),Cadastro!$G14)=0,Cadastro!$D14,0)) -> 14212.81 | F14: =IF($A14="","",IF(MOD(F$3-N(Cadastro!$F14),Cadastro!$G14)=0,Cadastro!$D14,0)) -> 14212.81 | G14: =IF($A14="","",IF(MOD(G$3-N(Cadastro!$F14),Cadastro!$G14)=0,Cadastro!$D14,0)) -> 14212.81 | H14: =IF($A14="","",IF(MOD(H$3-N(Cadastro!$F14),Cadastro!$G14)=0,Cadastro!$D14,0)) -> 14212.81 | I14: =IF($A14="","",IF(MOD(I$3-N(Cadastro!$F14),Cadastro!$G14)=0,Cadastro!$D14,0)) -> 14212.81 | J14: =IF($A14="","",IF(MOD(J$3-N(Cadastro!$F14),Cadastro!$G14)=0,Cadastro!$D14,0)) -> 14212.81 | O14: =IF($A14="","",SUM(C14:N14)) -> 113702.48 | P14: =IF(OR($A14="",COUNT(C14:N14)=0),"",AVERAGE(C14:N14)) -> 14212.81
A15: Combustivel | B15: =IF(Cadastro!C15="","",Cadastro!C15) -> Veiculo | C15: 4088.84 | D15: 2962.04 | E15: 5025.17 | F15: 4646.77 | G15: =3707.55 -> 3707.55 | H15: 3652.23 | I15: =3860.97+298.55 -> 4159.52 | J15: =2380.73+110.17 -> 2490.9 | O15: =IF($A15="","",SUM(C15:N15)) -> 30733.02 | P15: =IF(OR($A15="",COUNT(C15:N15)=0),"",AVERAGE(C15:N15)) -> 3841.6275
A16: Manutenção Veicular (peças, servico, revisao, licenciamento) | B16: =IF(Cadastro!C16="","",Cadastro!C16) -> Manutenção | E16: 1090 | F16: 300 | G16: 1127 | H16: 8106 | O16: =IF($A16="","",SUM(C16:N16)) -> 10623 | P16: =IF(OR($A16="",COUNT(C16:N16)=0),"",AVERAGE(C16:N16)) -> 2655.75
A17: =IF(Cadastro!B17="","",Cadastro!B17) -> Tubete | B17: =IF(Cadastro!C17="","",Cadastro!C17) -> Insumo | C17: 15443.95 | D17: 11826.15 | E17: 10391.35 | F17: 17694.65 | G17: 9866.8 | H17: 11657.35 | I17: 22825.5 | J17: 12575.45 | O17: =IF($A17="","",SUM(C17:N17)) -> 112281.2 | P17: =IF(OR($A17="",COUNT(C17:N17)=0),"",AVERAGE(C17:N17)) -> 14035.15
A18: =IF(Cadastro!B18="","",Cadastro!B18) -> Manutenção Predial | B18: =IF(Cadastro!C18="","",Cadastro!C18) -> Manutenção | C18: 1180 | D18: 1090 | E18: 150 | F18: 120 | G18: 100 | I18: 458 | J18: 1100 | O18: =IF($A18="","",SUM(C18:N18)) -> 4198 | P18: =IF(OR($A18="",COUNT(C18:N18)=0),"",AVERAGE(C18:N18)) -> 599.71429
A19: =IF(Cadastro!B19="","",Cadastro!B19) -> Seguro do Caminhão | B19: =IF(Cadastro!C19="","",Cadastro!C19) -> Veiculo | C19: 464.31167 | D19: 464.31167 | E19: 464.31167 | F19: 464.31167 | G19: 464.31167 | H19: 464.31167 | I19: 464.31167 | J19: 464.31167 | O19: =IF($A19="","",SUM(C19:N19)) -> 3714.4933 | P19: =IF(OR($A19="",COUNT(C19:N19)=0),"",AVERAGE(C19:N19)) -> 464.31167
A20: =IF(Cadastro!B20="","",Cadastro!B20) -> Parcela Caminhão | B20: =IF(Cadastro!C20="","",Cadastro!C20) -> Veiculo | C20: 3379.49 | D20: 3379.49 | E20: 3379.49 | F20: 3379.49 | G20: 3379.49 | H20: 3379.49 | I20: 3379.49 | J20: 3379.49 | K20: 3379.49 | O20: =IF($A20="","",SUM(C20:N20)) -> 30415.41 | P20: =IF(OR($A20="",COUNT(C20:N20)=0),"",AVERAGE(C20:N20)) -> 3379.49
A21: =IF(Cadastro!B21="","",Cadastro!B21) -> Despesas Pessoal (EPI, Farda e Ferramentas, Diaristas) | B21: Pessoal | F21: 363 | J21: 125 | O21: =IF($A21="","",SUM(C21:N21)) -> 488 | P21: =IF(OR($A21="",COUNT(C21:N21)=0),"",AVERAGE(C21:N21)) -> 244
A22: =IF(Cadastro!B22="","",Cadastro!B22) -> Outras Despesas | B22: Pessoal | C22: 0 | D22: 0 | E22: 0 | F22: 0 | G22: 0 | H22: 0 | I22: 0 | J22: 0 | O22: =IF($A22="","",SUM(C22:N22)) -> 0 | P22: =IF(OR($A22="",COUNT(C22:N22)=0),"",AVERAGE(C22:N22)) -> 0
A23: TOTAL DO MÊS | C23: =SUM(C5:C22) -> 42546.762 | D23: =SUM(D5:D22) -> 37412.162 | E23: =SUM(E5:E22) -> 35621.222 | F23: =SUM(F5:F22) -> 42089.122 | G23: =SUM(G5:G22) -> 33766.052 | H23: =SUM(H5:H22) -> 42950.282 | I23: =SUM(I5:I22) -> 46707.722 | J23: =SUM(J5:J22) -> 35256.052 | ... P23: =SUM(P5:P22) -> 41175.391
A24: Itens lançados | C24: =COUNT(C5:C21) -> 15 | D24: =COUNT(D5:D21) -> 15 | E24: =COUNT(E5:E21) -> 15 | F24: =COUNT(F5:F21) -> 17 | G24: =COUNT(G5:G21) -> 16 | H24: =COUNT(H5:H21) -> 15 | I24: =COUNT(I5:I21) -> 15 | J24: =COUNT(J5:J21) -> 16 | ... N24: =COUNT(N5:N21) -> 0
A25: Status do mês | C25: =IF(C24=0,"Pendente",IF(C24<COUNTA(Cadastro!$B$5:$B$22),"Parcial","Completo")) -> Parcial | D25: =IF(D24=0,"Pendente",IF(D24<COUNTA(Cadastro!$B$5:$B$22),"Parcial","Completo")) -> Parcial | E25: =IF(E24=0,"Pendente",IF(E24<COUNTA(Cadastro!$B$5:$B$22),"Parcial","Completo")) -> Parcial | F25: =IF(F24=0,"Pendente",IF(F24<COUNTA(Cadastro!$B$5:$B$22),"Parcial","Completo")) -> Parcial | G25: =IF(G24=0,"Pendente",IF(G24<COUNTA(Cadastro!$B$5:$B$22),"Parcial","Completo")) -> Parcial | H25: =IF(H24=0,"Pendente",IF(H24<COUNTA(Cadastro!$B$5:$B$22),"Parcial","Completo")) -> Parcial | I25: =IF(I24=0,"Pendente",IF(I24<COUNTA(Cadastro!$B$5:$B$22),"Parcial","Completo")) -> Parcial | J25: =IF(J24=0,"Pendente",IF(J24<COUNTA(Cadastro!$B$5:$B$22),"Parcial","Completo")) -> Parcial | ... N25: =IF(N24=0,"Pendente",IF(N24<COUNTA(Cadastro!$B$5:$B$22),"Parcial","Completo")) -> Pendente

Sheet Faturamento
A1: FATURAMENTO MENSAL — RECEITAS
A2: Preencha o faturamento (receita) de cada mês nas células em amarelo. Deixe em branco os meses ainda não faturados (ex.: Out, Nov, Dez).
A3: nº do mês → | C3: 1 | D3: 2 | E3: 3 | F3: 4 | G3: 5 | H3: 6 | I3: 7 | J3: 8 | K3: 9 | L3: 10 | M3: 11 | N3: 12
A4: Receita | B4: Tipo | C4: Jan | D4: Fev | E4: Mar | F4: Abr | G4: Mai | H4: Jun | I4: Jul | J4: Ago | K4: Set | L4: Out | M4: Nov | N4: Dez | O4: Total ano | P4: Média mensal
A5: Venda de mercadoria (NF-e) | B5: Mercadorias | O5: =IF(COUNT(C5:N5)=0,"",SUM(C5:N5)) | P5: =IF(COUNT(C5:N5)=0,"",AVERAGE(C5:N5))
O6: =IF(COUNT(C6:N6)=0,"",SUM(C6:N6)) | P6: =IF(COUNT(C6:N6)=0,"",AVERAGE(C6:N6))
O7: =IF(COUNT(C7:N7)=0,"",SUM(C7:N7)) | P7: =IF(COUNT(C7:N7)=0,"",AVERAGE(C7:N7))
O8: =IF(COUNT(C8:N8)=0,"",SUM(C8:N8)) | P8: =IF(COUNT(C8:N8)=0,"",AVERAGE(C8:N8))
O9: =IF(COUNT(C9:N9)=0,"",SUM(C9:N9)) | P9: =IF(COUNT(C9:N9)=0,"",AVERAGE(C9:N9))
O10: =IF(COUNT(C10:N10)=0,"",SUM(C10:N10)) | P10: =IF(COUNT(C10:N10)=0,"",AVERAGE(C10:N10))
O11: =IF(COUNT(C11:N11)=0,"",SUM(C11:N11)) | P11: =IF(COUNT(C11:N11)=0,"",AVERAGE(C11:N11))
O12: =IF(COUNT(C12:N12)=0,"",SUM(C12:N12)) | P12: =IF(COUNT(C12:N12)=0,"",AVERAGE(C12:N12))
O13: =IF(COUNT(C13:N13)=0,"",SUM(C13:N13)) | P13: =IF(COUNT(C13:N13)=0,"",AVERAGE(C13:N13))
O14: =IF(COUNT(C14:N14)=0,"",SUM(C14:N14)) | P14: =IF(COUNT(C14:N14)=0,"",AVERAGE(C14:N14))
A16: TOTAL DO MÊS | C16: =SUM(C5:C14) -> 0 | D16: =SUM(D5:D14) -> 0 | E16: =SUM(E5:E14) -> 0 | F16: =SUM(F5:F14) -> 0 | G16: =SUM(G5:G14) -> 0 | H16: =SUM(H5:H14) -> 0 | I16: =SUM(I5:I14) -> 0 | J16: =SUM(J5:J14) -> 0 | ... N16: =SUM(N5:N14) -> 0 | O16: =SUM(C16:N16) -> 0 | P16: =IF(COUNT(C17:N17)=0,"",O16/SUM(C17:N17)) -> #DIV/0!
A17: Meses faturados | C17: =IF(COUNT(C5:C14)=0,0,1) -> 0 | D17: =IF(COUNT(D5:D14)=0,0,1) -> 0 | E17: =IF(COUNT(E5:E14)=0,0,1) -> 0 | F17: =IF(COUNT(F5:F14)=0,0,1) -> 0 | G17: =IF(COUNT(G5:G14)=0,0,1) -> 0 | H17: =IF(COUNT(H5:H14)=0,0,1) -> 0 | I17: =IF(COUNT(I5:I14)=0,0,1) -> 0 | J17: =IF(COUNT(J5:J14)=0,0,1) -> 0 | ... N17: =IF(COUNT(N5:N14)=0,0,1) -> 0

Sheet Orçado
A1: ORÇADO (PREVISTO) — GERADO AUTOMATICAMENTE
A2: Não editar: calculado a partir da aba Cadastro (valor, periodicidade e mês de pagamento).
A3: nº do mês → | C3: 1 | D3: 2 | E3: 3 | F3: 4 | G3: 5 | H3: 6 | I3: 7 | J3: 8 | K3: 9 | L3: 10 | M3: 11 | N3: 12
A4: Despesa | B4: Categoria | C4: Jan | D4: Fev | E4: Mar | F4: Abr | G4: Mai | H4: Jun | I4: Jul | J4: Ago | K4: Set | L4: Out | M4: Nov | N4: Dez | O4: Total ano | P4: Média mensal
A5: =IF(Cadastro!B5="","",Cadastro!B5) -> Água | B5: =IF(Cadastro!C5="","",Cadastro!C5) -> Utilidades | C5: =IF($A5="","",IF(MOD(C$3-N(Cadastro!$F5),Cadastro!$G5)=0,Cadastro!$D5,0)) -> 93.19 | D5: =IF($A5="","",IF(MOD(D$3-N(Cadastro!$F5),Cadastro!$G5)=0,Cadastro!$D5,0)) -> 93.19 | E5: =IF($A5="","",IF(MOD(E$3-N(Cadastro!$F5),Cadastro!$G5)=0,Cadastro!$D5,0)) -> 93.19 | F5: =IF($A5="","",IF(MOD(F$3-N(Cadastro!$F5),Cadastro!$G5)=0,Cadastro!$D5,0)) -> 93.19 | G5: =IF($A5="","",IF(MOD(G$3-N(Cadastro!$F5),Cadastro!$G5)=0,Cadastro!$D5,0)) -> 93.19 | H5: =IF($A5="","",IF(MOD(H$3-N(Cadastro!$F5),Cadastro!$G5)=0,Cadastro!$D5,0)) -> 93.19 | I5: =IF($A5="","",IF(MOD(I$3-N(Cadastro!$F5),Cadastro!$G5)=0,Cadastro!$D5,0)) -> 93.19 | J5: =IF($A5="","",IF(MOD(J$3-N(Cadastro!$F5),Cadastro!$G5)=0,Cadastro!$D5,0)) -> 93.19 | O5: =IF($A5="","",SUM(C5:N5)) -> 745.52 | P5: =IF(OR($A5="",COUNT(C5:N5)=0),"",AVERAGE(C5:N5)) -> 93.19
A6: =IF(Cadastro!B6="","",Cadastro!B6) -> Energia | B6: =IF(Cadastro!C6="","",Cadastro!C6) -> Utilidades | C6: =IF($A6="","",IF(MOD(C$3-N(Cadastro!$F6),Cadastro!$G6)=0,Cadastro!$D6,0)) -> 145.19 | D6: =IF($A6="","",IF(MOD(D$3-N(Cadastro!$F6),Cadastro!$G6)=0,Cadastro!$D6,0)) -> 145.19 | E6: =IF($A6="","",IF(MOD(E$3-N(Cadastro!$F6),Cadastro!$G6)=0,Cadastro!$D6,0)) -> 145.19 | F6: =IF($A6="","",IF(MOD(F$3-N(Cadastro!$F6),Cadastro!$G6)=0,Cadastro!$D6,0)) -> 145.19 | G6: =IF($A6="","",IF(MOD(G$3-N(Cadastro!$F6),Cadastro!$G6)=0,Cadastro!$D6,0)) -> 145.19 | H6: =IF($A6="","",IF(MOD(H$3-N(Cadastro!$F6),Cadastro!$G6)=0,Cadastro!$D6,0)) -> 145.19 | I6: =IF($A6="","",IF(MOD(I$3-N(Cadastro!$F6),Cadastro!$G6)=0,Cadastro!$D6,0)) -> 145.19 | J6: =IF($A6="","",IF(MOD(J$3-N(Cadastro!$F6),Cadastro!$G6)=0,Cadastro!$D6,0)) -> 145.19 | O6: =IF($A6="","",SUM(C6:N6)) -> 1161.52 | P6: =IF(OR($A6="",COUNT(C6:N6)=0),"",AVERAGE(C6:N6)) -> 145.19
A7: =IF(Cadastro!B7="","",Cadastro!B7) -> Seguro galpão | B7: =IF(Cadastro!C7="","",Cadastro!C7) -> Seguros e Segurança | C7: 2569.27 | D7: =IF($A7="","",IF(MOD(D$3-N(Cadastro!$F7),Cadastro!$G7)=0,Cadastro!$D7,0)) -> 0 | F7: =IF($A7="","",IF(MOD(F$3-N(Cadastro!$F7),Cadastro!$G7)=0,Cadastro!$D7,0)) -> 0 | G7: =IF($A7="","",IF(MOD(G$3-N(Cadastro!$F7),Cadastro!$G7)=0,Cadastro!$D7,0)) -> 0 | H7: =IF($A7="","",IF(MOD(H$3-N(Cadastro!$F7),Cadastro!$G7)=0,Cadastro!$D7,0)) -> 0 | I7: =IF($A7="","",IF(MOD(I$3-N(Cadastro!$F7),Cadastro!$G7)=0,Cadastro!$D7,0)) -> 0 | J7: =IF($A7="","",IF(MOD(J$3-N(Cadastro!$F7),Cadastro!$G7)=0,Cadastro!$D7,0)) -> 0 | O7: =IF($A7="","",SUM(C7:N7)) -> 2569.27 | P7: =IF(OR($A7="",COUNT(C7:N7)=0),"",AVERAGE(C7:N7)) -> 367.03857
A8: =IF(Cadastro!B8="","",Cadastro!B8) -> Segurança Emive | B8: =IF(Cadastro!C8="","",Cadastro!C8) -> Seguros e Segurança | C8: =IF($A8="","",IF(MOD(C$3-N(Cadastro!$F8),Cadastro!$G8)=0,Cadastro!$D8,0)) -> 384 | D8: =IF($A8="","",IF(MOD(D$3-N(Cadastro!$F8),Cadastro!$G8)=0,Cadastro!$D8,0)) -> 384 | E8: =IF($A8="","",IF(MOD(E$3-N(Cadastro!$F8),Cadastro!$G8)=0,Cadastro!$D8,0)) -> 384 | F8: =IF($A8="","",IF(MOD(F$3-N(Cadastro!$F8),Cadastro!$G8)=0,Cadastro!$D8,0)) -> 384 | G8: =IF($A8="","",IF(MOD(G$3-N(Cadastro!$F8),Cadastro!$G8)=0,Cadastro!$D8,0)) -> 384 | H8: =IF($A8="","",IF(MOD(H$3-N(Cadastro!$F8),Cadastro!$G8)=0,Cadastro!$D8,0)) -> 384 | I8: =IF($A8="","",IF(MOD(I$3-N(Cadastro!$F8),Cadastro!$G8)=0,Cadastro!$D8,0)) -> 384 | J8: =IF($A8="","",IF(MOD(J$3-N(Cadastro!$F8),Cadastro!$G8)=0,Cadastro!$D8,0)) -> 384 | O8: =IF($A8="","",SUM(C8:N8)) -> 3072 | P8: =IF(OR($A8="",COUNT(C8:N8)=0),"",AVERAGE(C8:N8)) -> 384
A9: =IF(Cadastro!B9="","",Cadastro!B9) -> Dedetização | B9: =IF(Cadastro!C9="","",Cadastro!C9) -> Manutenção | C9: =IF($A9="","",IF(MOD(C$3-N(Cadastro!$F9),Cadastro!$G9)=0,Cadastro!$D9,0)) -> 300 | D9: =IF($A9="","",IF(MOD(D$3-N(Cadastro!$F9),Cadastro!$G9)=0,Cadastro!$D9,0)) -> 0 | E9: =IF($A9="","",IF(MOD(E$3-N(Cadastro!$F9),Cadastro!$G9)=0,Cadastro!$D9,0)) -> 0 | F9: =IF($A9="","",IF(MOD(F$3-N(Cadastro!$F9),Cadastro!$G9)=0,Cadastro!$D9,0)) -> 0 | G9: =IF($A9="","",IF(MOD(G$3-N(Cadastro!$F9),Cadastro!$G9)=0,Cadastro!$D9,0)) -> 0 | H9: =IF($A9="","",IF(MOD(H$3-N(Cadastro!$F9),Cadastro!$G9)=0,Cadastro!$D9,0)) -> 0 | I9: =IF($A9="","",IF(MOD(I$3-N(Cadastro!$F9),Cadastro!$G9)=0,Cadastro!$D9,0)) -> 300 | J9: =IF($A9="","",IF(MOD(J$3-N(Cadastro!$F9),Cadastro!$G9)=0,Cadastro!$D9,0)) -> 0 | O9: =IF($A9="","",SUM(C9:N9)) -> 600 | P9: =IF(OR($A9="",COUNT(C9:N9)=0),"",AVERAGE(C9:N9)) -> 75
A10: =IF(Cadastro!B10="","",Cadastro!B10) -> IPTU | B10: =IF(Cadastro!C10="","",Cadastro!C10) -> Impostos e Taxas | C10: =IF($A10="","",IF(MOD(C$3-N(Cadastro!$F10),Cadastro!$G10)=0,Cadastro!$D10,0)) -> 0 | D10: =IF($A10="","",IF(MOD(D$3-N(Cadastro!$F10),Cadastro!$G10)=0,Cadastro!$D10,0)) -> 2569.27 | E10: =IF($A10="","",IF(MOD(E$3-N(Cadastro!$F10),Cadastro!$G10)=0,Cadastro!$D10,0)) -> 0 | F10: =IF($A10="","",IF(MOD(F$3-N(Cadastro!$F10),Cadastro!$G10)=0,Cadastro!$D10,0)) -> 0 | G10: =IF($A10="","",IF(MOD(G$3-N(Cadastro!$F10),Cadastro!$G10)=0,Cadastro!$D10,0)) -> 0 | H10: =IF($A10="","",IF(MOD(H$3-N(Cadastro!$F10),Cadastro!$G10)=0,Cadastro!$D10,0)) -> 0 | I10: =IF($A10="","",IF(MOD(I$3-N(Cadastro!$F10),Cadastro!$G10)=0,Cadastro!$D10,0)) -> 0 | J10: =IF($A10="","",IF(MOD(J$3-N(Cadastro!$F10),Cadastro!$G10)=0,Cadastro!$D10,0)) -> 0 | O10: =IF($A10="","",SUM(C10:N10)) -> 2569.27 | P10: =IF(OR($A10="",COUNT(C10:N10)=0),"",AVERAGE(C10:N10)) -> 321.15875
A11: =IF(Cadastro!B11="","",Cadastro!B11) -> Controle de Ponto | B11: =IF(Cadastro!C11="","",Cadastro!C11) -> Pessoal | C11: =IF($A11="","",IF(MOD(C$3-N(Cadastro!$F11),Cadastro!$G11)=0,Cadastro!$D11,0)) -> 118 | D11: =IF($A11="","",IF(MOD(D$3-N(Cadastro!$F11),Cadastro!$G11)=0,Cadastro!$D11,0)) -> 118 | E11: =IF($A11="","",IF(MOD(E$3-N(Cadastro!$F11),Cadastro!$G11)=0,Cadastro!$D11,0)) -> 118 | F11: =IF($A11="","",IF(MOD(F$3-N(Cadastro!$F11),Cadastro!$G11)=0,Cadastro!$D11,0)) -> 118 | G11: =IF($A11="","",IF(MOD(G$3-N(Cadastro!$F11),Cadastro!$G11)=0,Cadastro!$D11,0)) -> 118 | H11: =IF($A11="","",IF(MOD(H$3-N(Cadastro!$F11),Cadastro!$G11)=0,Cadastro!$D11,0)) -> 118 | I11: =IF($A11="","",IF(MOD(I$3-N(Cadastro!$F11),Cadastro!$G11)=0,Cadastro!$D11,0)) -> 118 | J11: =IF($A11="","",IF(MOD(J$3-N(Cadastro!$F11),Cadastro!$G11)=0,Cadastro!$D11,0)) -> 118 | O11: =IF($A11="","",SUM(C11:N11)) -> 944 | P11: =IF(OR($A11="",COUNT(C11:N11)=0),"",AVERAGE(C11:N11)) -> 118
A12: =IF(Cadastro!B12="","",Cadastro!B12) -> Extintores | B12: =IF(Cadastro!C12="","",Cadastro!C12) -> Manutenção | C12: =IF($A12="","",IF(MOD(C$3-N(Cadastro!$F12),Cadastro!$G12)=0,Cadastro!$D12,0)) -> 0 | D12: =IF($A12="","",IF(MOD(D$3-N(Cadastro!$F12),Cadastro!$G12)=0,Cadastro!$D12,0)) -> 0 | E12: =IF($A12="","",IF(MOD(E$3-N(Cadastro!$F12),Cadastro!$G12)=0,Cadastro!$D12,0)) -> 0 | F12: =IF($A12="","",IF(MOD(F$3-N(Cadastro!$F12),Cadastro!$G12)=0,Cadastro!$D12,0)) -> 0 | G12: =IF($A12="","",IF(MOD(G$3-N(Cadastro!$F12),Cadastro!$G12)=0,Cadastro!$D12,0)) -> 0 | H12: =IF($A12="","",IF(MOD(H$3-N(Cadastro!$F12),Cadastro!$G12)=0,Cadastro!$D12,0)) -> 570 | I12: =IF($A12="","",IF(MOD(I$3-N(Cadastro!$F12),Cadastro!$G12)=0,Cadastro!$D12,0)) -> 0 | J12: =IF($A12="","",IF(MOD(J$3-N(Cadastro!$F12),Cadastro!$G12)=0,Cadastro!$D12,0)) -> 0 | O12: =IF($A12="","",SUM(C12:N12)) -> 570 | P12: =IF(OR($A12="",COUNT(C12:N12)=0),"",AVERAGE(C12:N12)) -> 71.25
A13: =IF(Cadastro!B13="","",Cadastro!B13) -> Internet | B13: =IF(Cadastro!C13="","",Cadastro!C13) -> Utilidades | C13: =IF($A13="","",IF(MOD(C$3-N(Cadastro!$F13),Cadastro!$G13)=0,Cadastro!$D13,0)) -> 167.71 | D13: =IF($A13="","",IF(MOD(D$3-N(Cadastro!$F13),Cadastro!$G13)=0,Cadastro!$D13,0)) -> 167.71 | E13: =IF($A13="","",IF(MOD(E$3-N(Cadastro!$F13),Cadastro!$G13)=0,Cadastro!$D13,0)) -> 167.71 | F13: =IF($A13="","",IF(MOD(F$3-N(Cadastro!$F13),Cadastro!$G13)=0,Cadastro!$D13,0)) -> 167.71 | G13: =IF($A13="","",IF(MOD(G$3-N(Cadastro!$F13),Cadastro!$G13)=0,Cadastro!$D13,0)) -> 167.71 | H13: =IF($A13="","",IF(MOD(H$3-N(Cadastro!$F13),Cadastro!$G13)=0,Cadastro!$D13,0)) -> 167.71 | I13: =IF($A13="","",IF(MOD(I$3-N(Cadastro!$F13),Cadastro!$G13)=0,Cadastro!$D13,0)) -> 167.71 | J13: =IF($A13="","",IF(MOD(J$3-N(Cadastro!$F13),Cadastro!$G13)=0,Cadastro!$D13,0)) -> 167.71 | O13: =IF($A13="","",SUM(C13:N13)) -> 1341.68 | P13: =IF(OR($A13="",COUNT(C13:N13)=0),"",AVERAGE(C13:N13)) -> 167.71
A14: =IF(Cadastro!B14="","",Cadastro!B14) -> Funcionários | B14: =IF(Cadastro!C14="","",Cadastro!C14) -> Pessoal | C14: =IF($A14="","",IF(MOD(C$3-N(Cadastro!$F14),Cadastro!$G14)=0,Cadastro!$D14,0)) -> 14212.81 | D14: =IF($A14="","",IF(MOD(D$3-N(Cadastro!$F14),Cadastro!$G14)=0,Cadastro!$D14,0)) -> 14212.81 | E14: =IF($A14="","",IF(MOD(E$3-N(Cadastro!$F14),Cadastro!$G14)=0,Cadastro!$D14,0)) -> 14212.81 | F14: =IF($A14="","",IF(MOD(F$3-N(Cadastro!$F14),Cadastro!$G14)=0,Cadastro!$D14,0)) -> 14212.81 | G14: =IF($A14="","",IF(MOD(G$3-N(Cadastro!$F14),Cadastro!$G14)=0,Cadastro!$D14,0)) -> 14212.81 | H14: =IF($A14="","",IF(MOD(H$3-N(Cadastro!$F14),Cadastro!$G14)=0,Cadastro!$D14,0)) -> 14212.81 | I14: =IF($A14="","",IF(MOD(I$3-N(Cadastro!$F14),Cadastro!$G14)=0,Cadastro!$D14,0)) -> 14212.81 | J14: =IF($A14="","",IF(MOD(J$3-N(Cadastro!$F14),Cadastro!$G14)=0,Cadastro!$D14,0)) -> 14212.81 | O14: =IF($A14="","",SUM(C14:N14)) -> 113702.48 | P14: =IF(OR($A14="",COUNT(C14:N14)=0),"",AVERAGE(C14:N14)) -> 14212.81
A15: Combustivel | B15: =IF(Cadastro!C15="","",Cadastro!C15) -> Veiculo | C15: 4088.84 | D15: 2962.04 | E15: 5025.17 | F15: 4646.77 | G15: =3707.55 -> 3707.55 | H15: 3652.23 | I15: =3860.97+298.55 -> 4159.52 | J15: =2380.73+110.17 -> 2490.9 | O15: =IF($A15="","",SUM(C15:N15)) -> 30733.02 | P15: =IF(OR($A15="",COUNT(C15:N15)=0),"",AVERAGE(C15:N15)) -> 3841.6275
A16: Manutenção Veicular (peças, servico, revisao, licenciamento) | B16: =IF(Cadastro!C16="","",Cadastro!C16) -> Manutenção | F16: 300 | G16: 1127 | H16: 8106 | O16: =IF($A16="","",SUM(C16:N16)) -> 9533 | P16: =IF(OR($A16="",COUNT(C16:N16)=0),"",AVERAGE(C16:N16)) -> 3177.6667
A17: =IF(Cadastro!B17="","",Cadastro!B17) -> Tubete | B17: =IF(Cadastro!C17="","",Cadastro!C17) -> Insumo | C17: 15443.95 | D17: 11826.15 | E17: 10391.35 | F17: 17694.65 | G17: 9866.8 | H17: 11657.35 | I17: 22825.5 | J17: 12575.45 | O17: =IF($A17="","",SUM(C17:N17)) -> 112281.2 | P17: =IF(OR($A17="",COUNT(C17:N17)=0),"",AVERAGE(C17:N17)) -> 14035.15
A18: =IF(Cadastro!B18="","",Cadastro!B18) -> Manutenção Predial | B18: =IF(Cadastro!C18="","",Cadastro!C18) -> Manutenção | C18: 1180 | D18: 1090 | E18: 150 | F18: 120 | G18: 100 | I18: 458 | J18: 1100 | O18: =IF($A18="","",SUM(C18:N18)) -> 4198 | P18: =IF(OR($A18="",COUNT(C18:N18)=0),"",AVERAGE(C18:N18)) -> 599.71429
A19: =IF(Cadastro!B19="","",Cadastro!B19) -> Seguro do Caminhão | B19: =IF(Cadastro!C19="","",Cadastro!C19) -> Veiculo | C19: 464.31167 | D19: 464.31167 | E19: 464.31167 | F19: 464.31167 | G19: 464.31167 | H19: 464.31167 | I19: 464.31167 | J19: 464.31167 | O19: =IF($A19="","",SUM(C19:N19)) -> 3714.4933 | P19: =IF(OR($A19="",COUNT(C19:N19)=0),"",AVERAGE(C19:N19)) -> 464.31167
A20: =IF(Cadastro!B20="","",Cadastro!B20) -> Parcela Caminhão | B20: =IF(Cadastro!C20="","",Cadastro!C20) -> Veiculo | C20: 3379.49 | D20: 3379.49 | E20: 3379.49 | F20: 3379.49 | G20: 3379.49 | H20: 3379.49 | I20: 3379.49 | J20: 3379.49 | O20: =IF($A20="","",SUM(C20:N20)) -> 27035.92 | P20: =IF(OR($A20="",COUNT(C20:N20)=0),"",AVERAGE(C20:N20)) -> 3379.49
A21: =IF(Cadastro!B21="","",Cadastro!B21) -> Despesas Pessoal (EPI, Farda e Ferramentas, Diaristas) | B21: Pessoal | F21: 363 | J21: 125 | O21: =IF($A21="","",SUM(C21:N21)) -> 488 | P21: =IF(OR($A21="",COUNT(C21:N21)=0),"",AVERAGE(C21:N21)) -> 244
A22: =IF(Cadastro!B22="","",Cadastro!B22) -> Outras Despesas | B22: Pessoal | C22: 0 | D22: 0 | E22: 0 | F22: 0 | G22: 0 | H22: 0 | I22: 0 | J22: 0 | O22: =IF($A22="","",SUM(C22:N22)) -> 0 | P22: =IF(OR($A22="",COUNT(C22:N22)=0),"",AVERAGE(C22:N22)) -> 0
A23: TOTAL DO MÊS | C23: =SUM(C5:C22) -> 42546.762 | D23: =SUM(D5:D22) -> 37412.162 | E23: =SUM(E5:E22) -> 34531.222 | F23: =SUM(F5:F22) -> 42089.122 | G23: =SUM(G5:G22) -> 33766.052 | H23: =SUM(H5:H22) -> 42950.282 | I23: =SUM(I5:I22) -> 46707.722 | J23: =SUM(J5:J22) -> 35256.052 | ... P23: =SUM(P5:P22) -> 41697.307

Sheet Cadastro
A1: CADASTRO DE DESPESAS FIXAS
A2: Células amarelas são editáveis. Para incluir nova despesa, preencha uma linha vazia — ela aparece automaticamente nas outras abas. | F2: Ano de referência: | G2: 2026
A4: Nº | B4: Despesa | C4: Categoria | D4: Valor (R$) | E4: Periodicidade | F4: Mês de pagamento (1-12) | G4: Intervalo (meses) | H4: Equivalente mensal (R$) | I4: Custo anual (R$) | J4: Observação | L4: Categorias
A5: 1 | B5: Água | C5: Utilidades | D5: 93.19 | E5: Mensal | G5: =IF(B5="","",IF(E5="Mensal",1,IF(E5="Trimestral",3,IF(E5="Semestral",6,12)))) -> 1 | H5: =IF(B5="","",D5/G5) -> 93.19 | L5: Pessoal
A6: 2 | B6: Energia | C6: Utilidades | D6: 145.19 | E6: Mensal | G6: =IF(B6="","",IF(E6="Mensal",1,IF(E6="Trimestral",3,IF(E6="Semestral",6,12)))) -> 1 | H6: =IF(B6="","",D6/G6) -> 145.19 | L6: Utilidades
A7: 3 | B7: Seguro galpão | C7: Seguros e Segurança | D7: 1744.5 | E7: Anual | F7: 3 | G7: =IF(B7="","",IF(E7="Mensal",1,IF(E7="Trimestral",3,IF(E7="Semestral",6,12)))) -> 12 | H7: =IF(B7="","",D7/G7) -> 145.375 | J7: Mês de pagamento estimado — ajuste | L7: Seguros e Segurança
A8: 4 | B8: Segurança Emive | C8: Seguros e Segurança | D8: 384 | E8: Mensal | G8: =IF(B8="","",IF(E8="Mensal",1,IF(E8="Trimestral",3,IF(E8="Semestral",6,12)))) -> 1 | H8: =IF(B8="","",D8/G8) -> 384 | L8: Manutenção
A9: 5 | B9: Dedetização | C9: Manutenção | D9: 300 | E9: Semestral | F9: 1 | G9: =IF(B9="","",IF(E9="Mensal",1,IF(E9="Trimestral",3,IF(E9="Semestral",6,12)))) -> 6 | H9: =IF(B9="","",D9/G9) -> 50 | J9: Paga em Jan e Jul (estimado) — ajuste | L9: Impostos e Taxas
A10: 6 | B10: IPTU | C10: Impostos e Taxas | D10: 2569.27 | E10: Anual | F10: 2 | G10: =IF(B10="","",IF(E10="Mensal",1,IF(E10="Trimestral",3,IF(E10="Semestral",6,12)))) -> 12 | H10: =IF(B10="","",D10/G10) -> 214.10583 | J10: Mês de pagamento estimado — ajuste | L10: Outros
A11: 7 | B11: Controle de Ponto | C11: Pessoal | D11: 118 | E11: Mensal | G11: =IF(B11="","",IF(E11="Mensal",1,IF(E11="Trimestral",3,IF(E11="Semestral",6,12)))) -> 1 | H11: =IF(B11="","",D11/G11) -> 118 | L11: Veiculo
A12: 8 | B12: Extintores | C12: Manutenção | D12: 570 | E12: Anual | F12: 6 | G12: =IF(B12="","",IF(E12="Mensal",1,IF(E12="Trimestral",3,IF(E12="Semestral",6,12)))) -> 12 | H12: =IF(B12="","",D12/G12) -> 47.5 | J12: Mês de recarga estimado — ajuste | L12: Abastecimento
A13: 9 | B13: Internet | C13: Utilidades | D13: 167.71 | E13: Mensal | G13: =IF(B13="","",IF(E13="Mensal",1,IF(E13="Trimestral",3,IF(E13="Semestral",6,12)))) -> 1 | H13: =IF(B13="","",D13/G13) -> 167.71 | L13: Insumo
A14: 10 | B14: Funcionários | C14: Pessoal | D14: 14212.81 | E14: Mensal | G14: =IF(B14="","",IF(E14="Mensal",1,IF(E14="Trimestral",3,IF(E14="Semestral",6,12)))) -> 1 | H14: =IF(B14="","",D14/G14) -> 14212.81
A15: 14 | B15: Combustivel RRG7C78 | C15: Veiculo | G15: =IF(B15="","",IF(E15="Mensal",1,IF(E15="Trimestral",3,IF(E15="Semestral",6,12)))) -> 12 | H15: =IF(B15="","",D15/G15) -> 0
A16: 15 | B16: Manutenção Veicular (peças, servico, revisao, licenciamento) | C16: Manutenção | G16: =IF(B16="","",IF(E16="Mensal",1,IF(E16="Trimestral",3,IF(E16="Semestral",6,12)))) -> 12 | H16: =IF(B16="","",D16/G16) -> 0 | I16: =IF(B16="","",H16*12) -> 0
A17: 16 | B17: Tubete | C17: Insumo | G17: =IF(B17="","",IF(E17="Mensal",1,IF(E17="Trimestral",3,IF(E17="Semestral",6,12)))) -> 12 | H17: =IF(B17="","",D17/G17) -> 0 | I17: =IF(B17="","",H17*12) -> 0
A18: 17 | B18: Manutenção Predial | C18: Manutenção | G18: =IF(B18="","",IF(E18="Mensal",1,IF(E18="Trimestral",3,IF(E18="Semestral",6,12)))) -> 12 | H18: =IF(B18="","",D18/G18) -> 0 | I18: =IF(B18="","",H18*12) -> 0
A19: 18 | B19: Seguro do Caminhão | C19: Veiculo | G19: =IF(B19="","",IF(E19="Mensal",1,IF(E19="Trimestral",3,IF(E19="Semestral",6,12)))) -> 12 | H19: =IF(B19="","",D19/G19) -> 0 | I19: =IF(B19="","",H19*12) -> 0
A20: 19 | B20: Parcela Caminhão | C20: Veiculo | G20: =IF(B20="","",IF(E20="Mensal",1,IF(E20="Trimestral",3,IF(E20="Semestral",6,12)))) -> 12 | H20: =IF(B20="","",D20/G20) -> 0 | I20: =IF(B20="","",H20*12) -> 0
A21: 20 | B21: Despesas Pessoal (EPI, Farda e Ferramentas, Diaristas) | C21: Pessoal | G21: =IF(B21="","",IF(E21="Mensal",1,IF(E21="Trimestral",3,IF(E21="Semestral",6,12)))) -> 12 | H21: =IF(B21="","",D21/G21) -> 0 | I21: =IF(B21="","",H21*12) -> 0
A22: 21 | B22: Outras Despesas | C22: Pessoal | G22: =IF(B22="","",IF(E22="Mensal",1,IF(E22="Trimestral",3,IF(E22="Semestral",6,12)))) -> 12 | H22: =IF(B22="","",D22/G22) -> 0 | I22: =IF(B22="","",H22*12) -> 0
B23: TOTAL | H23: =SUM(H5:H22) -> 15577.881 | I23: =SUM(I5:I22) -> 0
